Workbook

Sheet How to use
A1: KPI tracking workbook | B1: Source of the numbers shown on the City of Durango Performance Dashboard.
A3: Where to type
A4: KPI Data sheet | B4: Add one row each time a KPI gets a new result. This is the sheet you will use most.
A5: KPI Catalog sheet | B5: One row per KPI, set up once: its name, where it appears on the dashboard, and how its status is judged.
A6: Dashboard Items sheet | B6: Reference only. Look up the ID of a Work System, Key Service, Program or Objective. Do not edit.
A8: Where a KPI appears
A9: Level | B9: Pick Work System, Key Service or Program. This decides which part of the Work System View the KPI shows in.
A10: Dashboard Item ID | B10: The ID of the specific item at that level, from the Dashboard Items sheet: ws… for a Work System, ks… for a Key Service, p… for a Program.
A11: Item Name (auto) | B11: Fills in by itself to show what the ID points to. Do not type in the shaded columns. "ID not found" or "Level does not match ID" means one of the two cells to its left needs fixing.
A12: Also Show Under | B12: Optional. IDs of other places to show the same KPI, separated by commas, such as ks7, ob14. Use an Objective ID (ob…) to show it in the Strategic Plan Goal View, or another Key Service, Program or Work System ID to show it there too (for example, a Program KPI that is also a headline measure for its Key Service). The KPI counts toward the color of any Objective it is under.
A13: Also Under (auto) | B13: Fills in by itself to show what a single ID points to. With several IDs it cannot check them; the script does that when you run it.
A15: Rules for KPI Data
A16: KPI ID | B16: Must match an ID in the KPI Catalog sheet exactly.
A17: Period | B17: The label shown on the dashboard, such as 2026 or FY2026 Q1. Enter rows oldest first; the last row is treated as the latest result.
A18: Segment | B18: Leave blank for the main (headline) result. Fill in for a breakdown of that same period, such as Full-time.
A19: Value | B19: Type percentages as 79.3 for 79.3%, not 0.793. Leave blank or type N/A when there is no result.
A20: Target | B20: The City's own goal for that period. Leave blank if there is none; the dashboard will say "Target not set".
A21: Benchmark | B21: An outside comparison for that period, such as an industry or peer-city figure. Leave blank if there is none; the dashboard will say "Benchmark not set".
A22: Note | B22: Optional. Shown under the chart as a footnote for that period.
A24: How status is worked out
A25: Status Based On | B25: In the KPI Catalog: choose whether the status is judged against the Target or the Benchmark. If that number is blank for the latest period, the KPI shows no status.
A26: On Track | B26: The latest result meets the target (or benchmark, if chosen above), or misses it by no more than "On Track Within %" (5% of the target unless changed in the catalog).
A27: At Risk | B27: The result misses the target by more than that, up to "Off Track Beyond %" (15% unless changed).
A28: Off Track | B28: The result misses the target by more than "Off Track Beyond %".
A29: Drives Status | B29: Yes: this KPI sets the color of every Key Service and Program it is shown under. No: the KPI is shown but does not change any color. Has no effect on Work Systems or Objectives: a Work System always takes its color from its Key Services, and an Objective from the Programs tagged to it plus any KPIs shown under it.
A31: After editing
A32: Publish | B32: Save this file in the repository folder, run python3 build_kpi_data.py in the VS Code terminal, then commit and sync. The script lists any problems and leaves the live numbers untouched until they are fixed.
A33: Public file | B33: If the repository is public, this workbook is public too. Only enter numbers that are ready to publish.

Sheet KPI Catalog
A1: KPI ID | B1: KPI Name | C1: Level | D1: Dashboard Item ID | E1: Item Name (auto) | F1: Also Show Under | G1: Also Under (auto) | H1: Unit | I1: Decimals | J1: Higher Is Better | K1: Status Based On | L1: On Track Within % | M1: Off Track Beyond % | N1: Drives Status | O1: Update Frequency | P1: Owner | Q1: Source | R1: Description | S1: Footnote
A2: HR-EMPENG | B2: Employee engagement score | C2: Key Service | D2: ks5 | E2: =IF(D2="","",IFERROR(IF(INDEX('Dashboard Items'!$B$2:$B$500,MATCH(D2,'Dashboard Items'!$A$2:$A$500,0))="Objective","Objectives go in the next column",IF(OR(C2="",INDEX('Dashboard Items'!$B$2:$B$500,MATCH(D2,'Dashboard Items'!$A$2:$A$500,0))=C2),INDEX('Dashboard Items'!$C$2:$C$500,MATCH(D2,'Dashboard Items'!$A$2:$A$500,0)),"Level does not match ID")),"ID not found")) -> Human Resources & Workforce Development | F2: ob18 | G2: =IF(F2="","",IF(ISNUMBER(SEARCH(",",F2)),"Several items (the script lists them)",IFERROR(INDEX('Dashboard Items'!$B$2:$B$500,MATCH(F2,'Dashboard Items'!$A$2:$A$500,0))&": "&INDEX('Dashboard Items'!$C$2:$C$500,MATCH(F2,'Dashboard Items'!$A$2:$A$500,0)),"ID not found"))) -> Objective: 6.1 Employee Growth and Retention | H2: percent | I2: 1 | J2: Yes | K2: Target | L2: 5 | M2: 15 | N2: Yes | O2: Every 2 years | P2: HR Director | Q2: Employee Survey | R2: Overall engagement score from the City employee survey, compared with the survey benchmark.
A3: HR-TIMETOHIRE | B3: Time to hire | C3: Program | D3: p24 | E3: =IF(D3="","",IFERROR(IF(INDEX('Dashboard Items'!$B$2:$B$500,MATCH(D3,'Dashboard Items'!$A$2:$A$500,0))="Objective","Objectives go in the next column",IF(OR(C3="",INDEX('Dashboard Items'!$B$2:$B$500,MATCH(D3,'Dashboard Items'!$A$2:$A$500,0))=C3),INDEX('Dashboard Items'!$C$2:$C$500,MATCH(D3,'Dashboard Items'!$A$2:$A$500,0)),"Level does not match ID")),"ID not found")) -> Recruitment and Retention
A4: HR-VACANCYRATE | B4: Full time vacancy rate | C4: Program | D4: p24 | E4: =IF(D4="","",IFERROR(IF(INDEX('Dashboard Items'!$B$2:$B$500,MATCH(D4,'Dashboard Items'!$A$2:$A$500,0))="Objective","Objectives go in the next column",IF(OR(C4="",INDEX('Dashboard Items'!$B$2:$B$500,MATCH(D4,'Dashboard Items'!$A$2:$A$500,0))=C4),INDEX('Dashboard Items'!$C$2:$C$500,MATCH(D4,'Dashboard Items'!$A$2:$A$500,0)),"Level does not match ID")),"ID not found")) -> Recruitment and Retention
A5: HR-QUITRATE | B5: 90 day quit rate | C5: Program | D5: p24 | E5: =IF(D5="","",IFERROR(IF(INDEX('Dashboard Items'!$B$2:$B$500,MATCH(D5,'Dashboard Items'!$A$2:$A$500,0))="Objective","Objectives go in the next column",IF(OR(C5="",INDEX('Dashboard Items'!$B$2:$B$500,MATCH(D5,'Dashboard Items'!$A$2:$A$500,0))=C5),INDEX('Dashboard Items'!$C$2:$C$500,MATCH(D5,'Dashboard Items'!$A$2:$A$500,0)),"Level does not match ID")),"ID not found")) -> Recruitment and Retention
A6: HR-CLICKTHRURATE | B6: Job clickthrough rate | C6: Program | D6: p24 | E6: =IF(D6="","",IFERROR(IF(INDEX('Dashboard Items'!$B$2:$B$500,MATCH(D6,'Dashboard Items'!$A$2:$A$500,0))="Objective","Objectives go in the next column",IF(OR(C6="",INDEX('Dashboard Items'!$B$2:$B$500,MATCH(D6,'Dashboard Items'!$A$2:$A$500,0))=C6),INDEX('Dashboard Items'!$C$2:$C$500,MATCH(D6,'Dashboard Items'!$A$2:$A$500,0)),"Level does not match ID")),"ID not found")) -> Recruitment and Retention
A7: RISK-DOTCOMP | B7: DOT compliance score | C7: Program | D7: p27 | E7: =IF(D7="","",IFERROR(IF(INDEX('Dashboard Items'!$B$2:$B$500,MATCH(D7,'Dashboard Items'!$A$2:$A$500,0))="Objective","Objectives go in the next column",IF(OR(C7="",INDEX('Dashboard Items'!$B$2:$B$500,MATCH(D7,'Dashboard Items'!$A$2:$A$500,0))=C7),INDEX('Dashboard Items'!$C$2:$C$500,MATCH(D7,'Dashboard Items'!$A$2:$A$500,0)),"Level does not match ID")),"ID not found")) -> Risk Management | P7: Safety / Risk Administrator
A8: RISK-EMOD | B8: Experience modificationscore | C8: Program | D8: p27 | E8: =IF(D8="","",IFERROR(IF(INDEX('Dashboard Items'!$B$2:$B$500,MATCH(D8,'Dashboard Items'!$A$2:$A$500,0))="Objective","Objectives go in the next column",IF(OR(C8="",INDEX('Dashboard Items'!$B$2:$B$500,MATCH(D8,'Dashboard Items'!$A$2:$A$500,0))=C8),INDEX('Dashboard Items'!$C$2:$C$500,MATCH(D8,'Dashboard Items'!$A$2:$A$500,0)),"Level does not match ID")),"ID not found")) -> Risk Management | J8: No | P8: Safety / Risk Administrator
A9: RISK-PREMIUMSCORE | B9: Workers' compensation | C9: Program | D9: p27 | E9: =IF(D9="","",IFERROR(IF(INDEX('Dashboard Items'!$B$2:$B$500,MATCH(D9,'Dashboard Items'!$A$2:$A$500,0))="Objective","Objectives go in the next column",IF(OR(C9="",INDEX('Dashboard Items'!$B$2:$B$500,MATCH(D9,'Dashboard Items'!$A$2:$A$500,0))=C9),INDEX('Dashboard Items'!$C$2:$C$500,MATCH(D9,'Dashboard Items'!$A$2:$A$500,0)),"Level does not match ID")),"ID not found")) -> Risk Management | P9: Safety / Risk Administrator
A10: RISK-WORKCOMP | B10: Loss run report for workers' comp | C10: Program | D10: p27 | E10: =IF(D10="","",IFERROR(IF(INDEX('Dashboard Items'!$B$2:$B$500,MATCH(D10,'Dashboard Items'!$A$2:$A$500,0))="Objective","Objectives go in the next column",IF(OR(C10="",INDEX('Dashboard Items'!$B$2:$B$500,MATCH(D10,'Dashboard Items'!$A$2:$A$500,0))=C10),INDEX('Dashboard Items'!$C$2:$C$500,MATCH(D10,'Dashboard Items'!$A$2:$A$500,0)),"Level does not match ID")),"ID not found")) -> Risk Management | P10: Safety / Risk Administrator
A11: RISK-PROPCLAIMS | B11: Property casualty claims | C11: Program | D11: p27 | E11: =IF(D11="","",IFERROR(IF(INDEX('Dashboard Items'!$B$2:$B$500,MATCH(D11,'Dashboard Items'!$A$2:$A$500,0))="Objective","Objectives go in the next column",IF(OR(C11="",INDEX('Dashboard Items'!$B$2:$B$500,MATCH(D11,'Dashboard Items'!$A$2:$A$500,0))=C11),INDEX('Dashboard Items'!$C$2:$C$500,MATCH(D11,'Dashboard Items'!$A$2:$A$500,0)),"Level does not match ID")),"ID not found")) -> Risk Management | P11: Safety / Risk Administrator
A12: RISK-ACCIDENTREV | B12: Accident review board scoring | C12: Program | D12: p27 | E12: =IF(D12="","",IFERROR(IF(INDEX('Dashboard Items'!$B$2:$B$500,MATCH(D12,'Dashboard Items'!$A$2:$A$500,0))="Objective","Objectives go in the next column",IF(OR(C12="",INDEX('Dashboard Items'!$B$2:$B$500,MATCH(D12,'Dashboard Items'!$A$2:$A$500,0))=C12),INDEX('Dashboard Items'!$C$2:$C$500,MATCH(D12,'Dashboard Items'!$A$2:$A$500,0)),"Level does not match ID")),"ID not found")) -> Risk Management | J12: No | P12: Safety / Risk Administrator
A13: RISK-TRAININGS | B13: Safety trainings | C13: Program | D13: p27 | E13: =IF(D13="","",IFERROR(IF(INDEX('Dashboard Items'!$B$2:$B$500,MATCH(D13,'Dashboard Items'!$A$2:$A$500,0))="Objective","Objectives go in the next column",IF(OR(C13="",INDEX('Dashboard Items'!$B$2:$B$500,MATCH(D13,'Dashboard Items'!$A$2:$A$500,0))=C13),INDEX('Dashboard Items'!$C$2:$C$500,MATCH(D13,'Dashboard Items'!$A$2:$A$500,0)),"Level does not match ID")),"ID not found")) -> Risk Management | J13: Yes | P13: Safety / Risk Administrator
A14: IT-UPTIME | B14: Network uptime | C14: Program | D14: p30 | E14: =IF(D14="","",IFERROR(IF(INDEX('Dashboard Items'!$B$2:$B$500,MATCH(D14,'Dashboard Items'!$A$2:$A$500,0))="Objective","Objectives go in the next column",IF(OR(C14="",INDEX('Dashboard Items'!$B$2:$B$500,MATCH(D14,'Dashboard Items'!$A$2:$A$500,0))=C14),INDEX('Dashboard Items'!$C$2:$C$500,MATCH(D14,'Dashboard Items'!$A$2:$A$500,0)),"Level does not match ID")),"ID not found")) -> Network and Infrastructure Management | F14: ks7, ob14 | G14: =IF(F14="","",IF(ISNUMBER(SEARCH(",",F14)),"Several items (the script lists them)",IFERROR(INDEX('Dashboard Items'!$B$2:$B$500,MATCH(F14,'Dashboard Items'!$A$2:$A$500,0))&": "&INDEX('Dashboard Items'!$C$2:$C$500,MATCH(F14,'Dashboard Items'!$A$2:$A$500,0)),"ID not found"))) -> Several items (the script lists them) | H14: percent | I14: 2 | J14: Yes | K14: Target | L14: 5 | M14: 15 | N14: Yes | O14: Every year | P14: IT Director | Q14: Solar Winds
A15: IT-PITSURV | B15: Point in time help desk survey | C15: Program | D15: p34 | E15: =IF(D15="","",IFERROR(IF(INDEX('Dashboard Items'!$B$2:$B$500,MATCH(D15,'Dashboard Items'!$A$2:$A$500,0))="Objective","Objectives go in the next column",IF(OR(C15="",INDEX('Dashboard Items'!$B$2:$B$500,MATCH(D15,'Dashboard Items'!$A$2:$A$500,0))=C15),INDEX('Dashboard Items'!$C$2:$C$500,MATCH(D15,'Dashboard Items'!$A$2:$A$500,0)),"Level does not match ID")),"ID not found")) -> Help Desk | F15: ks7 | G15: =IF(F15="","",IF(ISNUMBER(SEARCH(",",F15)),"Several items (the script lists them)",IFERROR(INDEX('Dashboard Items'!$B$2:$B$500,MATCH(F15,'Dashboard Items'!$A$2:$A$500,0))&": "&INDEX('Dashboard Items'!$C$2:$C$500,MATCH(F15,'Dashboard Items'!$A$2:$A$500,0)),"ID not found"))) -> Key Service: Information Technology Services | H15: percent | I15: 1 | J15: Yes | K15: Target | L15: 5 | M15: 15 | N15: Yes | O15: Every year | P15: IT Director | Q15: SysAid
A16: IT-TIXSLA | B16: Help desk ticket SLA compliance | C16: Program | D16: p34 | E16: =IF(D16="","",IFERROR(IF(INDEX('Dashboard Items'!$B$2:$B$500,MATCH(D16,'Dashboard Items'!$A$2:$A$500,0))="Objective","Objectives go in the next column",IF(OR(C16="",INDEX('Dashboard Items'!$B$2:$B$500,MATCH(D16,'Dashboard Items'!$A$2:$A$500,0))=C16),INDEX('Dashboard Items'!$C$2:$C$500,MATCH(D16,'Dashboard Items'!$A$2:$A$500,0)),"Level does not match ID")),"ID not found")) -> Help Desk | F16: ks7 | G16: =IF(F16="","",IF(ISNUMBER(SEARCH(",",F16)),"Several items (the script lists them)",IFERROR(INDEX('Dashboard Items'!$B$2:$B$500,MATCH(F16,'Dashboard Items'!$A$2:$A$500,0))&": "&INDEX('Dashboard Items'!$C$2:$C$500,MATCH(F16,'Dashboard Items'!$A$2:$A$500,0)),"ID not found"))) -> Key Service: Information Technology Services | H16: percent | I16: 2 | J16: Yes | K16: Target | L16: 5 | M16: 15 | N16: Yes | O16: Every year | P16: IT Director | Q16: SysAid
A17: IT-PHISHRATE | B17: Organization phish prone rate | C17: Program | D17: p31 | E17: =IF(D17="","",IFERROR(IF(INDEX('Dashboard Items'!$B$2:$B$500,MATCH(D17,'Dashboard Items'!$A$2:$A$500,0))="Objective","Objectives go in the next column",IF(OR(C17="",INDEX('Dashboard Items'!$B$2:$B$500,MATCH(D17,'Dashboard Items'!$A$2:$A$500,0))=C17),INDEX('Dashboard Items'!$C$2:$C$500,MATCH(D17,'Dashboard Items'!$A$2:$A$500,0)),"Level does not match ID")),"ID not found")) -> Cybersecurity | F17: ks7 | G17: =IF(F17="","",IF(ISNUMBER(SEARCH(",",F17)),"Several items (the script lists them)",IFERROR(INDEX('Dashboard Items'!$B$2:$B$500,MATCH(F17,'Dashboard Items'!$A$2:$A$500,0))&": "&INDEX('Dashboard Items'!$C$2:$C$500,MATCH(F17,'Dashboard Items'!$A$2:$A$500,0)),"ID not found"))) -> Key Service: Information Technology Services | H17: percent | I17: 2 | J17: No | K17: Target | L17: 5 | M17: 15 | N17: Yes | O17: Every Quarter | P17: IT Director | Q17: KnowBe4
A18: LIB-CIRCTOTAL | B18: Total circulation | C18: Program | D18: p82 | E18: =IF(D18="","",IFERROR(IF(INDEX('Dashboard Items'!$B$2:$B$500,MATCH(D18,'Dashboard Items'!$A$2:$A$500,0))="Objective","Objectives go in the next column",IF(OR(C18="",INDEX('Dashboard Items'!$B$2:$B$500,MATCH(D18,'Dashboard Items'!$A$2:$A$500,0))=C18),INDEX('Dashboard Items'!$C$2:$C$500,MATCH(D18,'Dashboard Items'!$A$2:$A$500,0)),"Level does not match ID")),"ID not found")) -> Circulation Services | G18: =IF(F18="","",IF(ISNUMBER(SEARCH(",",F18)),"Several items (the script lists them)",IFERROR(INDEX('Dashboard Items'!$B$2:$B$500,MATCH(F18,'Dashboard Items'!$A$2:$A$500,0))&": "&INDEX('Dashboard Items'!$C$2:$C$500,MATCH(F18,'Dashboard Items'!$A$2:$A$500,0)),"ID not found")))
A19: LIB-CIRCPHYS | B19: Physical circulation | C19: Program | D19: p82 | E19: =IF(D19="","",IFERROR(IF(INDEX('Dashboard Items'!$B$2:$B$500,MATCH(D19,'Dashboard Items'!$A$2:$A$500,0))="Objective","Objectives go in the next column",IF(OR(C19="",INDEX('Dashboard Items'!$B$2:$B$500,MATCH(D19,'Dashboard Items'!$A$2:$A$500,0))=C19),INDEX('Dashboard Items'!$C$2:$C$500,MATCH(D19,'Dashboard Items'!$A$2:$A$500,0)),"Level does not match ID")),"ID not found")) -> Circulation Services | G19: =IF(F19="","",IF(ISNUMBER(SEARCH(",",F19)),"Several items (the script lists them)",IFERROR(INDEX('Dashboard Items'!$B$2:$B$500,MATCH(F19,'Dashboard Items'!$A$2:$A$500,0))&": "&INDEX('Dashboard Items'!$C$2:$C$500,MATCH(F19,'Dashboard Items'!$A$2:$A$500,0)),"ID not found")))
A20: LIB_CIRCDIGI | B20: Digital circulation | C20: Program | D20: p82 | E20: =IF(D20="","",IFERROR(IF(INDEX('Dashboard Items'!$B$2:$B$500,MATCH(D20,'Dashboard Items'!$A$2:$A$500,0))="Objective","Objectives go in the next column",IF(OR(C20="",INDEX('Dashboard Items'!$B$2:$B$500,MATCH(D20,'Dashboard Items'!$A$2:$A$500,0))=C20),INDEX('Dashboard Items'!$C$2:$C$500,MATCH(D20,'Dashboard Items'!$A$2:$A$500,0)),"Level does not match ID")),"ID not found")) -> Circulation Services | G20: =IF(F20="","",IF(ISNUMBER(SEARCH(",",F20)),"Several items (the script lists them)",IFERROR(INDEX('Dashboard Items'!$B$2:$B$500,MATCH(F20,'Dashboard Items'!$A$2:$A$500,0))&": "&INDEX('Dashboard Items'!$C$2:$C$500,MATCH(F20,'Dashboard Items'!$A$2:$A$500,0)),"ID not found")))
A21: LIB-VISITS | B21: Visitation | C21: Program | D21: p115 | E21: =IF(D21="","",IFERROR(IF(INDEX('Dashboard Items'!$B$2:$B$500,MATCH(D21,'Dashboard Items'!$A$2:$A$500,0))="Objective","Objectives go in the next column",IF(OR(C21="",INDEX('Dashboard Items'!$B$2:$B$500,MATCH(D21,'Dashboard Items'!$A$2:$A$500,0))=C21),INDEX('Dashboard Items'!$C$2:$C$500,MATCH(D21,'Dashboard Items'!$A$2:$A$500,0)),"Level does not match ID")),"ID not found")) -> Community Space | F21: ks17 | G21: =IF(F21="","",IF(ISNUMBER(SEARCH(",",F21)),"Several items (the script lists them)",IFERROR(INDEX('Dashboard Items'!$B$2:$B$500,MATCH(F21,'Dashboard Items'!$A$2:$A$500,0))&": "&INDEX('Dashboard Items'!$C$2:$C$500,MATCH(F21,'Dashboard Items'!$A$2:$A$500,0)),"ID not found"))) -> Key Service: Library & Learning Services | H21: number | I21: 0 | J21: Yes | K21: Target | L21: 5 | M21: 15 | N21: Yes | O21: Every Year | P21: Library Director
A22: LIB-ROOMRENTALS | B22: Program room rentals | C22: Program | D22: p115 | E22: =IF(D22="","",IFERROR(IF(INDEX('Dashboard Items'!$B$2:$B$500,MATCH(D22,'Dashboard Items'!$A$2:$A$500,0))="Objective","Objectives go in the next column",IF(OR(C22="",INDEX('Dashboard Items'!$B$2:$B$500,MATCH(D22,'Dashboard Items'!$A$2:$A$500,0))=C22),INDEX('Dashboard Items'!$C$2:$C$500,MATCH(D22,'Dashboard Items'!$A$2:$A$500,0)),"Level does not match ID")),"ID not found")) -> Community Space | G22: =IF(F22="","",IF(ISNUMBER(SEARCH(",",F22)),"Several items (the script lists them)",IFERROR(INDEX('Dashboard Items'!$B$2:$B$500,MATCH(F22,'Dashboard Items'!$A$2:$A$500,0))&": "&INDEX('Dashboard Items'!$C$2:$C$500,MATCH(F22,'Dashboard Items'!$A$2:$A$500,0)),"ID not found")))
A23: LIB-COMPUSE | B23: Total computer use | C23: Program | D23: p83 | E23: =IF(D23="","",IFERROR(IF(INDEX('Dashboard Items'!$B$2:$B$500,MATCH(D23,'Dashboard Items'!$A$2:$A$500,0))="Objective","Objectives go in the next column",IF(OR(C23="",INDEX('Dashboard Items'!$B$2:$B$500,MATCH(D23,'Dashboard Items'!$A$2:$A$500,0))=C23),INDEX('Dashboard Items'!$C$2:$C$500,MATCH(D23,'Dashboard Items'!$A$2:$A$500,0)),"Level does not match ID")),"ID not found")) -> Digital Learning | G23: =IF(F23="","",IF(ISNUMBER(SEARCH(",",F23)),"Several items (the script lists them)",IFERROR(INDEX('Dashboard Items'!$B$2:$B$500,MATCH(F23,'Dashboard Items'!$A$2:$A$500,0))&": "&INDEX('Dashboard Items'!$C$2:$C$500,MATCH(F23,'Dashboard Items'!$A$2:$A$500,0)),"ID not found")))
A24: LIB-UNIQWIRELESS | B24: Unique wireless use | C24: Program | D24: p83 | E24: =IF(D24="","",IFERROR(IF(INDEX('Dashboard Items'!$B$2:$B$500,MATCH(D24,'Dashboard Items'!$A$2:$A$500,0))="Objective","Objectives go in the next column",IF(OR(C24="",INDEX('Dashboard Items'!$B$2:$B$500,MATCH(D24,'Dashboard Items'!$A$2:$A$500,0))=C24),INDEX('Dashboard Items'!$C$2:$C$500,MATCH(D24,'Dashboard Items'!$A$2:$A$500,0)),"Level does not match ID")),"ID not found")) -> Digital Learning | G24: =IF(F24="","",IF(ISNUMBER(SEARCH(",",F24)),"Several items (the script lists them)",IFERROR(INDEX('Dashboard Items'!$B$2:$B$500,MATCH(F24,'Dashboard Items'!$A$2:$A$500,0))&": "&INDEX('Dashboard Items'!$C$2:$C$500,MATCH(F24,'Dashboard Items'!$A$2:$A$500,0)),"ID not found")))
A25: LIB-REFQUEST | B25: Reference questions | C25: Program | D25: p86 | E25: =IF(D25="","",IFERROR(IF(INDEX('Dashboard Items'!$B$2:$B$500,MATCH(D25,'Dashboard Items'!$A$2:$A$500,0))="Objective","Objectives go in the next column",IF(OR(C25="",INDEX('Dashboard Items'!$B$2:$B$500,MATCH(D25,'Dashboard Items'!$A$2:$A$500,0))=C25),INDEX('Dashboard Items'!$C$2:$C$500,MATCH(D25,'Dashboard Items'!$A$2:$A$500,0)),"Level does not match ID")),"ID not found")) -> Cultural Programming | G25: =IF(F25="","",IF(ISNUMBER(SEARCH(",",F25)),"Several items (the script lists them)",IFERROR(INDEX('Dashboard Items'!$B$2:$B$500,MATCH(F25,'Dashboard Items'!$A$2:$A$500,0))&": "&INDEX('Dashboard Items'!$C$2:$C$500,MATCH(F25,'Dashboard Items'!$A$2:$A$500,0)),"ID not found")))
A26: LIB-SOCIALENG | B26: Total social media user engagement | C26: Program | D26: p86 | E26: =IF(D26="","",IFERROR(IF(INDEX('Dashboard Items'!$B$2:$B$500,MATCH(D26,'Dashboard Items'!$A$2:$A$500,0))="Objective","Objectives go in the next column",IF(OR(C26="",INDEX('Dashboard Items'!$B$2:$B$500,MATCH(D26,'Dashboard Items'!$A$2:$A$500,0))=C26),INDEX('Dashboard Items'!$C$2:$C$500,MATCH(D26,'Dashboard Items'!$A$2:$A$500,0)),"Level does not match ID")),"ID not found")) -> Cultural Programming | G26: =IF(F26="","",IF(ISNUMBER(SEARCH(",",F26)),"Several items (the script lists them)",IFERROR(INDEX('Dashboard Items'!$B$2:$B$500,MATCH(F26,'Dashboard Items'!$A$2:$A$500,0))&": "&INDEX('Dashboard Items'!$C$2:$C$500,MATCH(F26,'Dashboard Items'!$A$2:$A$500,0)),"ID not found")))
A27: LIB-PATRONPPROG | B27: Patron per program | C27: Program | D27: p86 | E27: =IF(D27="","",IFERROR(IF(INDEX('Dashboard Items'!$B$2:$B$500,MATCH(D27,'Dashboard Items'!$A$2:$A$500,0))="Objective","Objectives go in the next column",IF(OR(C27="",INDEX('Dashboard Items'!$B$2:$B$500,MATCH(D27,'Dashboard Items'!$A$2:$A$500,0))=C27),INDEX('Dashboard Items'!$C$2:$C$500,MATCH(D27,'Dashboard Items'!$A$2:$A$500,0)),"Level does not match ID")),"ID not found")) -> Cultural Programming | G27: =IF(F27="","",IF(ISNUMBER(SEARCH(",",F27)),"Several items (the script lists them)",IFERROR(INDEX('Dashboard Items'!$B$2:$B$500,MATCH(F27,'Dashboard Items'!$A$2:$A$500,0))&": "&INDEX('Dashboard Items'!$C$2:$C$500,MATCH(F27,'Dashboard Items'!$A$2:$A$500,0)),"ID not found")))
A28: LIB-PROGATTEND | B28: Total program attendance | C28: Program | D28: p86 | E28: =IF(D28="","",IFERROR(IF(INDEX('Dashboard Items'!$B$2:$B$500,MATCH(D28,'Dashboard Items'!$A$2:$A$500,0))="Objective","Objectives go in the next column",IF(OR(C28="",INDEX('Dashboard Items'!$B$2:$B$500,MATCH(D28,'Dashboard Items'!$A$2:$A$500,0))=C28),INDEX('Dashboard Items'!$C$2:$C$500,MATCH(D28,'Dashboard Items'!$A$2:$A$500,0)),"Level does not match ID")),"ID not found")) -> Cultural Programming | G28: =IF(F28="","",IF(ISNUMBER(SEARCH(",",F28)),"Several items (the script lists them)",IFERROR(INDEX('Dashboard Items'!$B$2:$B$500,MATCH(F28,'Dashboard Items'!$A$2:$A$500,0))&": "&INDEX('Dashboard Items'!$C$2:$C$500,MATCH(F28,'Dashboard Items'!$A$2:$A$500,0)),"ID not found")))
A29: LIB-OUTREACHCON | B29: Total outreach contacts | C29: Program | D29: p86 | E29: =IF(D29="","",IFERROR(IF(INDEX('Dashboard Items'!$B$2:$B$500,MATCH(D29,'Dashboard Items'!$A$2:$A$500,0))="Objective","Objectives go in the next column",IF(OR(C29="",INDEX('Dashboard Items'!$B$2:$B$500,MATCH(D29,'Dashboard Items'!$A$2:$A$500,0))=C29),INDEX('Dashboard Items'!$C$2:$C$500,MATCH(D29,'Dashboard Items'!$A$2:$A$500,0)),"Level does not match ID")),"ID not found")) -> Cultural Programming | G29: =IF(F29="","",IF(ISNUMBER(SEARCH(",",F29)),"Several items (the script lists them)",IFERROR(INDEX('Dashboard Items'!$B$2:$B$500,MATCH(F29,'Dashboard Items'!$A$2:$A$500,0))&": "&INDEX('Dashboard Items'!$C$2:$C$500,MATCH(F29,'Dashboard Items'!$A$2:$A$500,0)),"ID not found")))
A30: CLERK-CLICKTHRURATE | B30: Click through rate on City's election landing page | C30: Program | D30: p8 | E30: =IF(D30="","",IFERROR(IF(INDEX('Dashboard Items'!$B$2:$B$500,MATCH(D30,'Dashboard Items'!$A$2:$A$500,0))="Objective","Objectives go in the next column",IF(OR(C30="",INDEX('Dashboard Items'!$B$2:$B$500,MATCH(D30,'Dashboard Items'!$A$2:$A$500,0))=C30),INDEX('Dashboard Items'!$C$2:$C$500,MATCH(D30,'Dashboard Items'!$A$2:$A$500,0)),"Level does not match ID")),"ID not found")) -> Elections Administration | G30: =IF(F30="","",IF(ISNUMBER(SEARCH(",",F30)),"Several items (the script lists them)",IFERROR(INDEX('Dashboard Items'!$B$2:$B$500,MATCH(F30,'Dashboard Items'!$A$2:$A$500,0))&": "&INDEX('Dashboard Items'!$C$2:$C$500,MATCH(F30,'Dashboard Items'!$A$2:$A$500,0)),"ID not found")))
A31: CLERK-QRESPRATE | B31: Response rate for public election related questions | C31: Program | D31: p8 | E31: =IF(D31="","",IFERROR(IF(INDEX('Dashboard Items'!$B$2:$B$500,MATCH(D31,'Dashboard Items'!$A$2:$A$500,0))="Objective","Objectives go in the next column",IF(OR(C31="",INDEX('Dashboard Items'!$B$2:$B$500,MATCH(D31,'Dashboard Items'!$A$2:$A$500,0))=C31),INDEX('Dashboard Items'!$C$2:$C$500,MATCH(D31,'Dashboard Items'!$A$2:$A$500,0)),"Level does not match ID")),"ID not found")) -> Elections Administration | G31: =IF(F31="","",IF(ISNUMBER(SEARCH(",",F31)),"Several items (the script lists them)",IFERROR(INDEX('Dashboard Items'!$B$2:$B$500,MATCH(F31,'Dashboard Items'!$A$2:$A$500,0))&": "&INDEX('Dashboard Items'!$C$2:$C$500,MATCH(F31,'Dashboard Items'!$A$2:$A$500,0)),"ID not found")))
A32: CLERK-VOTERTURNOUT | B32: Voter turnout (%) | C32: Program | D32: p8 | E32: =IF(D32="","",IFERROR(IF(INDEX('Dashboard Items'!$B$2:$B$500,MATCH(D32,'Dashboard Items'!$A$2:$A$500,0))="Objective","Objectives go in the next column",IF(OR(C32="",INDEX('Dashboard Items'!$B$2:$B$500,MATCH(D32,'Dashboard Items'!$A$2:$A$500,0))=C32),INDEX('Dashboard Items'!$C$2:$C$500,MATCH(D32,'Dashboard Items'!$A$2:$A$500,0)),"Level does not match ID")),"ID not found")) -> Elections Administration | F32: ks2 | G32: =IF(F32="","",IF(ISNUMBER(SEARCH(",",F32)),"Several items (the script lists them)",IFERROR(INDEX('Dashboard Items'!$B$2:$B$500,MATCH(F32,'Dashboard Items'!$A$2:$A$500,0))&": "&INDEX('Dashboard Items'!$C$2:$C$500,MATCH(F32,'Dashboard Items'!$A$2:$A$500,0)),"ID not found"))) -> Key Service: City Clerk & Records Management
A33: CLERK-LOGICTEST | B33: Logic and accuracy test | C33: Program | D33: p8 | E33: =IF(D33="","",IFERROR(IF(INDEX('Dashboard Items'!$B$2:$B$500,MATCH(D33,'Dashboard Items'!$A$2:$A$500,0))="Objective","Objectives go in the next column",IF(OR(C33="",INDEX('Dashboard Items'!$B$2:$B$500,MATCH(D33,'Dashboard Items'!$A$2:$A$500,0))=C33),INDEX('Dashboard Items'!$C$2:$C$500,MATCH(D33,'Dashboard Items'!$A$2:$A$500,0)),"Level does not match ID")),"ID not found")) -> Elections Administration | G33: =IF(F33="","",IF(ISNUMBER(SEARCH(",",F33)),"Several items (the script lists them)",IFERROR(INDEX('Dashboard Items'!$B$2:$B$500,MATCH(F33,'Dashboard Items'!$A$2:$A$500,0))&": "&INDEX('Dashboard Items'!$C$2:$C$500,MATCH(F33,'Dashboard Items'!$A$2:$A$500,0)),"ID not found")))
A34: CLERK-CORARESPRATE | B34: Records request response rate | C34: Program | D34: p7 | E34: =IF(D34="","",IFERROR(IF(INDEX('Dashboard Items'!$B$2:$B$500,MATCH(D34,'Dashboard Items'!$A$2:$A$500,0))="Objective","Objectives go in the next column",IF(OR(C34="",INDEX('Dashboard Items'!$B$2:$B$500,MATCH(D34,'Dashboard Items'!$A$2:$A$500,0))=C34),INDEX('Dashboard Items'!$C$2:$C$500,MATCH(D34,'Dashboard Items'!$A$2:$A$500,0)),"Level does not match ID")),"ID not found")) -> Records Management | F34: ks2 | G34: =IF(F34="","",IF(ISNUMBER(SEARCH(",",F34)),"Several items (the script lists them)",IFERROR(INDEX('Dashboard Items'!$B$2:$B$500,MATCH(F34,'Dashboard Items'!$A$2:$A$500,0))&": "&INDEX('Dashboard Items'!$C$2:$C$500,MATCH(F34,'Dashboard Items'!$A$2:$A$500,0)),"ID not found"))) -> Key Service: City Clerk & Records Management
A35: CLERK-AGENDAPOST | B35: Agenda posting time | C35: Program | D35: p6 | E35: =IF(D35="","",IFERROR(IF(INDEX('Dashboard Items'!$B$2:$B$500,MATCH(D35,'Dashboard Items'!$A$2:$A$500,0))="Objective","Objectives go in the next column",IF(OR(C35="",INDEX('Dashboard Items'!$B$2:$B$500,MATCH(D35,'Dashboard Items'!$A$2:$A$500,0))=C35),INDEX('Dashboard Items'!$C$2:$C$500,MATCH(D35,'Dashboard Items'!$A$2:$A$500,0)),"Level does not match ID")),"ID not found")) -> Council/Board Support | F35: ks2 | G35: =IF(F35="","",IF(ISNUMBER(SEARCH(",",F35)),"Several items (the script lists them)",IFERROR(INDEX('Dashboard Items'!$B$2:$B$500,MATCH(F35,'Dashboard Items'!$A$2:$A$500,0))&": "&INDEX('Dashboard Items'!$C$2:$C$500,MATCH(F35,'Dashboard Items'!$A$2:$A$500,0)),"ID not found"))) -> Key Service: City Clerk & Records Management
A36: CLERK-LIQMARJLIC | B36: Liquor and marijuana license turnaround | C36: Program | D36: p29 | E36: =IF(D36="","",IFERROR(IF(INDEX('Dashboard Items'!$B$2:$B$500,MATCH(D36,'Dashboard Items'!$A$2:$A$500,0))="Objective","Objectives go in the next column",IF(OR(C36="",INDEX('Dashboard Items'!$B$2:$B$500,MATCH(D36,'Dashboard Items'!$A$2:$A$500,0))=C36),INDEX('Dashboard Items'!$C$2:$C$500,MATCH(D36,'Dashboard Items'!$A$2:$A$500,0)),"Level does not match ID")),"ID not found")) -> Licensing | F36: ks2 | G36: =IF(F36="","",IF(ISNUMBER(SEARCH(",",F36)),"Several items (the script lists them)",IFERROR(INDEX('Dashboard Items'!$B$2:$B$500,MATCH(F36,'Dashboard Items'!$A$2:$A$500,0))&": "&INDEX('Dashboard Items'!$C$2:$C$500,MATCH(F36,'Dashboard Items'!$A$2:$A$500,0)),"ID not found"))) -> Key Service: City Clerk & Records Management
A37: CLERK-BIZLIC | B37: Business license turnaround time | C37: Program | D37: p29 | E37: =IF(D37="","",IFERROR(IF(INDEX('Dashboard Items'!$B$2:$B$500,MATCH(D37,'Dashboard Items'!$A$2:$A$500,0))="Objective","Objectives go in the next column",IF(OR(C37="",INDEX('Dashboard Items'!$B$2:$B$500,MATCH(D37,'Dashboard Items'!$A$2:$A$500,0))=C37),INDEX('Dashboard Items'!$C$2:$C$500,MATCH(D37,'Dashboard Items'!$A$2:$A$500,0)),"Level does not match ID")),"ID not found")) -> Licensing | F37: ks2 | G37: =IF(F37="","",IF(ISNUMBER(SEARCH(",",F37)),"Several items (the script lists them)",IFERROR(INDEX('Dashboard Items'!$B$2:$B$500,MATCH(F37,'Dashboard Items'!$A$2:$A$500,0))&": "&INDEX('Dashboard Items'!$C$2:$C$500,MATCH(F37,'Dashboard Items'!$A$2:$A$500,0)),"ID not found"))) -> Key Service: City Clerk & Records Management
A38: MUNI-SPECCOURT | B38: # cases resolved through graduating from specialty court | C38: Program | D38: p58 | E38: =IF(D38="","",IFERROR(IF(INDEX('Dashboard Items'!$B$2:$B$500,MATCH(D38,'Dashboard Items'!$A$2:$A$500,0))="Objective","Objectives go in the next column",IF(OR(C38="",INDEX('Dashboard Items'!$B$2:$B$500,MATCH(D38,'Dashboard Items'!$A$2:$A$500,0))=C38),INDEX('Dashboard Items'!$C$2:$C$500,MATCH(D38,'Dashboard Items'!$A$2:$A$500,0)),"Level does not match ID")),"ID not found")) -> Specialty Court | F38: ks12 | G38: =IF(F38="","",IF(ISNUMBER(SEARCH(",",F38)),"Several items (the script lists them)",IFERROR(INDEX('Dashboard Items'!$B$2:$B$500,MATCH(F38,'Dashboard Items'!$A$2:$A$500,0))&": "&INDEX('Dashboard Items'!$C$2:$C$500,MATCH(F38,'Dashboard Items'!$A$2:$A$500,0)),"ID not found"))) -> Key Service: Municipal Court | H38: percent | I38: 2 | J38: Yes | K38: Target | L38: 5 | M38: 15 | N38: Yes | O38: Every year | P38: Public Information Officer | Q38: Instagram, Facebook, LinkedIn, TikTok
A39: PIO-ENGRATE | B39: Social media engagement rate | C39: Program | D39: p12 | E39: =IF(D39="","",IFERROR(IF(INDEX('Dashboard Items'!$B$2:$B$500,MATCH(D39,'Dashboard Items'!$A$2:$A$500,0))="Objective","Objectives go in the next column",IF(OR(C39="",INDEX('Dashboard Items'!$B$2:$B$500,MATCH(D39,'Dashboard Items'!$A$2:$A$500,0))=C39),INDEX('Dashboard Items'!$C$2:$C$500,MATCH(D39,'Dashboard Items'!$A$2:$A$500,0)),"Level does not match ID")),"ID not found")) -> Social Media | F39: ks3 | G39: =IF(F39="","",IF(ISNUMBER(SEARCH(",",F39)),"Several items (the script lists them)",IFERROR(INDEX('Dashboard Items'!$B$2:$B$500,MATCH(F39,'Dashboard Items'!$A$2:$A$500,0))&": "&INDEX('Dashboard Items'!$C$2:$C$500,MATCH(F39,'Dashboard Items'!$A$2:$A$500,0)),"ID not found"))) -> Key Service: Public Information & Community Engagement
E40: =IF(D40="","",IFERROR(IF(INDEX('Dashboard Items'!$B$2:$B$500,MATCH(D40,'Dashboard Items'!$A$2:$A$500,0))="Objective","Objectives go in the next column",IF(OR(C40="",INDEX('Dashboard Items'!$B$2:$B$500,MATCH(D40,'Dashboard Items'!$A$2:$A$500,0))=C40),INDEX('Dashboard Items'!$C$2:$C$500,MATCH(D40,'Dashboard Items'!$A$2:$A$500,0)),"Level does not match ID")),"ID not found")) | G40: =IF(F40="","",IF(ISNUMBER(SEARCH(",",F40)),"Several items (the script lists them)",IFERROR(INDEX('Dashboard Items'!$B$2:$B$500,MATCH(F40,'Dashboard Items'!$A$2:$A$500,0))&": "&INDEX('Dashboard Items'!$C$2:$C$500,MATCH(F40,'Dashboard Items'!$A$2:$A$500,0)),"ID not found")))
...

Sheet KPI Data
A1: KPI ID | B1: Period | C1: Segment | D1: Value | E1: Target | F1: Benchmark | G1: Note
A2: HR-EMPENG | B2: 2022 | D2: 69 | F2: 76.6 | G2: Full-time employees only
A3: HR-EMPENG | B3: 2024 | D3: 81.3 | F3: 75.1 | G3: Full-time employees only
A4: HR-EMPENG | B4: 2026 | D4: 79.3 | F4: 76.6
A5: HR-EMPENG | B5: 2026 | C5: Full-time | D5: 79.9
A6: HR-EMPENG | B6: 2026 | C6: PT/Seasonal | D6: 78.2
A7: IT-UPTIME | B7: 2020 | D7: 99.89 | E7: 99.99 | F7: 99.999
A8: IT-UPTIME | B8: 2021 | D8: 99.98 | E8: 99.99 | F8: 99.999
A9: IT-UPTIME | B9: 2022 | D9: 99.92 | E9: 99.99 | F9: 99.999
A10: IT-UPTIME | B10: 2023 | D10: 99.91 | E10: 99.99 | F10: 99.999
A11: IT-UPTIME | B11: 2024 | D11: 99.79 | E11: 99.99 | F11: 99.999
A12: IT-UPTIME | B12: 2025 | D12: 99.85 | E12: 99.99 | F12: 99.999
A13: IT-PITSURV | B13: 2022 | D13: 80 | E13: 85
A14: IT-PITSURV | B14: 2023 | D14: 89.86 | E14: 85
A15: IT-PITSURV | B15: 2024 | D15: 85.71 | E15: 85
A16: IT-PITSURV | B16: 2025 | D16: 89.97 | E16: 85
A17: IT-TIXSLA | B17: 2022 | C17: Minor | E17: 95 | F17: 100
A18: IT-TIXSLA | B18: 2022 | C18: Normal | E18: 95 | F18: 100
A19: IT-TIXSLA | B19: 2022 | C19: Urgent | E19: 95 | F19: 100
A20: IT-TIXSLA | B20: 2022 | C20: Critical | E20: 95 | F20: 100
A21: IT-TIXSLA | B21: 2023 | C21: Minor | E21: 95 | F21: 100
A22: IT-TIXSLA | B22: 2023 | C22: Normal | E22: 95 | F22: 100
A23: IT-TIXSLA | B23: 2023 | C23: Urgent | E23: 95 | F23: 100
A24: IT-TIXSLA | B24: 2023 | C24: Critical | E24: 95 | F24: 100
A25: IT-TIXSLA | B25: 2024 | C25: Minor | E25: 95 | F25: 100
A26: IT-TIXSLA | B26: 2024 | C26: Normal | E26: 95 | F26: 100
A27: IT-TIXSLA | B27: 2024 | C27: Urgent | E27: 95 | F27: 100
A28: IT-TIXSLA | B28: 2024 | C28: Critical | E28: 95 | F28: 100
... A32: IT-TIXSLA | B32: 2025 | C32: Critical | E32: 95 | F32: 100
A33: IT-PHISHRATE | B33: 2020-Q1 | D33: 8.9 | E33: 3.9 | F33: 3.9
A34: IT-PHISHRATE | B34: 2020-Q2 | D34: 2.4 | E34: 3.9 | F34: 3.9
A35: IT-PHISHRATE | B35: 2022-Q2 | D35: 1.05 | E35: 3.9 | F35: 3.9
A36: IT-PHISHRATE | B36: 2022-Q3 | D36: 0.9 | E36: 3.9 | F36: 3.9
A37: IT-PHISHRATE | B37: 2022-Q4 | D37: 0.63333333 | E37: 3.9 | F37: 3.9
A38: IT-PHISHRATE | B38: 2023-Q1 | D38: 0.7 | E38: 3.9 | F38: 3.9
A39: IT-PHISHRATE | B39: 2023-Q2 | D39: 1.1333333 | E39: 3.9 | F39: 3.9
A40: IT-PHISHRATE | B40: 2023-Q3 | D40: 0.56666667 | E40: 3.9 | F40: 3.9
A41: IT-PHISHRATE | B41: 2023-Q4 | D41: 0.83333333 | E41: 3.9 | F41: 3.9
A42: IT-PHISHRATE | B42: 2024-Q1 | D42: 1.5333333 | E42: 3.9 | F42: 3.9
A43: IT-PHISHRATE | B43: 2024-Q2 | D43: 1.1 | E43: 3.9 | F43: 3.9
...

Sheet Dashboard Items
A1: ID | B1: Level | C1: Name | D1: Key Service (for Programs) | E1: Work System | F1: Goal (for Objectives)
A2: ws1 | B2: Work System | C2: Leadership and Governance
A3: ws2 | B3: Work System | C3: Financial and Internal Services
A4: ws3 | B4: Work System | C4: Community Growth and Economic Vitality
A5: ws4 | B5: Work System | C5: Public Safety
A6: ws5 | B6: Work System | C6: Infrastructure
A7: ws6 | B7: Work System | C7: Parks, Recreation and Cultural Services
A8: ks1 | B8: Key Service | C8: Administrative Leadership & Governance | E8: Leadership and Governance
A9: ks2 | B9: Key Service | C9: City Clerk & Records Management | E9: Leadership and Governance
A10: ks3 | B10: Key Service | C10: Public Information & Community Engagement | E10: Leadership and Governance
A11: ks4 | B11: Key Service | C11: Financial Management & Accountability | E11: Financial and Internal Services
A12: ks5 | B12: Key Service | C12: Human Resources & Workforce Development | E12: Financial and Internal Services
A13: ks6 | B13: Key Service | C13: Legal Services | E13: Financial and Internal Services
A14: ks7 | B14: Key Service | C14: Information Technology Services | E14: Financial and Internal Services
A15: ks8 | B15: Key Service | C15: Community Development & Planning | E15: Community Growth and Economic Vitality
A16: ks9 | B16: Key Service | C16: Economic Prosperity & Business Support | E16: Community Growth and Economic Vitality
A17: ks10 | B17: Key Service | C17: Sustainability & Environmental Stewardship | E17: Community Growth and Economic Vitality
A18: ks11 | B18: Key Service | C18: Public Safety Services | E18: Public Safety
A19: ks12 | B19: Key Service | C19: Municipal Court | E19: Public Safety
... A26: ks20 | B26: Key Service | C26: Recreation & Community Programs | E26: Parks, Recreation and Cultural Services
A27: p1 | B27: Program | C27: Executive Leadership Programs | D27: Administrative Leadership & Governance | E27: Leadership and Governance
A28: p2 | B28: Program | C28: Strategic Planning | D28: Administrative Leadership & Governance | E28: Leadership and Governance
A29: p3 | B29: Program | C29: Organizational Performance Management | D29: Administrative Leadership & Governance | E29: Leadership and Governance
A30: p4 | B30: Program | C30: Ethics and Compliance Oversight | D30: Administrative Leadership & Governance | E30: Leadership and Governance
A31: p5 | B31: Program | C31: Customer Service | D31: Administrative Leadership & Governance | E31: Leadership and Governance
A32: p7 | B32: Program | C32: Records Management | D32: City Clerk & Records Management | E32: Leadership and Governance
A33: p8 | B33: Program | C33: Elections Administration | D33: City Clerk & Records Management | E33: Leadership and Governance
A34: p6 | B34: Program | C34: Council/Board Support | D34: City Clerk & Records Management | E34: Leadership and Governance
A35: p29 | B35: Program | C35: Licensing | D35: City Clerk & Records Management | E35: Leadership and Governance
A36: p11 | B36: Program | C36: Public Outreach | D36: Public Information & Community Engagement | E36: Leadership and Governance
A37: p12 | B37: Program | C37: Social Media | D37: Public Information & Community Engagement | E37: Leadership and Governance
A38: p13 | B38: Program | C38: Community Engagement Initiatives | D38: Public Information & Community Engagement | E38: Leadership and Governance
... A137: p121 | B137: Program | C137: Childcare | D137: Recreation & Community Programs | E137: Parks, Recreation and Cultural Services
A138: ob1 | B138: Objective | C138: 1.1 Financial Sustainability and Innovation | F138: Organizational Stewardship
A139: ob2 | B139: Objective | C139: 1.2 Community Partnerships and Inclusion | F139: Organizational Stewardship
A140: ob3 | B140: Objective | C140: 1.3 Environmental Stewardship | F140: Organizational Stewardship
A141: ob4 | B141: Objective | C141: 2.1 Affordable, Multigenerational Housing | F141: Innovative Housing and Economic Development
A142: ob5 | B142: Objective | C142: 2.2 Economic Growth and Entrepreneurship | F142: Innovative Housing and Economic Development
A143: ob6 | B143: Objective | C143: 2.3 Community Character and Investments | F143: Innovative Housing and Economic Development
A144: ob7 | B144: Objective | C144: 3.1 Public Safety and Emergency Services | F144: Safety & Quality of Life
...
